<?xml version="1.0" encoding="UTF-8"?>
<!-- Generated by org.testng.reporters.JUnitReportReporter -->
<testsuite hostname="NODE518" name="learn.java.com.automation.Data" tests="4" failures="2" timestamp="27 Nov 2017 03:19:14 GMT" time="75.779" errors="0">
  <testcase name="Login" time="22.968" classname="learn.java.com.automation.Data"/>
  <testcase name="Login" time="16.907" classname="learn.java.com.automation.Data">
    <failure type="java.lang.AssertionError" message="Login not succesful expected [https://www.facebook.com/] but found [https://www.facebook.com/login.php?login_attempt=1&amp;lwv=100]">
      <![CDATA[java.lang.AssertionError: Login not succesful expected [https://www.facebook.com/] but found [https://www.facebook.com/login.php?login_attempt=1&lwv=100]
	at org.testng.Assert.fail(Assert.java:94)
	at org.testng.Assert.failNotEquals(Assert.java:496)
	at org.testng.Assert.assertEquals(Assert.java:125)
	at org.testng.Assert.assertEquals(Assert.java:178)
	at learn.java.com.automation.Data.Login(Data.java:44)
	at sun.reflect.NativeMethodAccessorImpl.invoke0(Native Method)
	at sun.reflect.NativeMethodAccessorImpl.invoke(Unknown Source)
	at sun.reflect.DelegatingMethodAccessorImpl.invoke(Unknown Source)
	at java.lang.reflect.Method.invoke(Unknown Source)
	at org.testng.internal.MethodInvocationHelper.invokeMethod(MethodInvocationHelper.java:85)
	at org.testng.internal.Invoker.invokeMethod(Invoker.java:639)
	at org.testng.internal.Invoker.invokeTestMethod(Invoker.java:816)
	at org.testng.internal.Invoker.invokeTestMethods(Invoker.java:1124)
	at org.testng.internal.TestMethodWorker.invokeTestMethods(TestMethodWorker.java:125)
	at org.testng.internal.TestMethodWorker.run(TestMethodWorker.java:108)
	at org.testng.TestRunner.privateRun(TestRunner.java:774)
	at org.testng.TestRunner.run(TestRunner.java:624)
	at org.testng.SuiteRunner.runTest(SuiteRunner.java:359)
	at org.testng.SuiteRunner.runSequentially(SuiteRunner.java:354)
	at org.testng.SuiteRunner.privateRun(SuiteRunner.java:312)
	at org.testng.SuiteRunner.run(SuiteRunner.java:261)
	at org.testng.SuiteRunnerWorker.runSuite(SuiteRunnerWorker.java:52)
	at org.testng.SuiteRunnerWorker.run(SuiteRunnerWorker.java:86)
	at org.testng.TestNG.runSuitesSequentially(TestNG.java:1215)
	at org.testng.TestNG.runSuitesLocally(TestNG.java:1140)
	at org.testng.TestNG.run(TestNG.java:1048)
	at org.testng.remote.AbstractRemoteTestNG.run(AbstractRemoteTestNG.java:114)
	at org.testng.remote.RemoteTestNG.initAndRun(RemoteTestNG.java:251)
	at org.testng.remote.RemoteTestNG.main(RemoteTestNG.java:77)
]]>
    </failure>
  </testcase> <!-- Login -->
  <testcase name="Login" time="20.124" classname="learn.java.com.automation.Data"/>
  <testcase name="Login" time="15.780" classname="learn.java.com.automation.Data">
    <failure type="java.lang.AssertionError" message="Login not succesful expected [https://www.facebook.com/] but found [https://www.facebook.com/login.php?login_attempt=1&amp;lwv=100]">
      <![CDATA[java.lang.AssertionError: Login not succesful expected [https://www.facebook.com/] but found [https://www.facebook.com/login.php?login_attempt=1&lwv=100]
	at org.testng.Assert.fail(Assert.java:94)
	at org.testng.Assert.failNotEquals(Assert.java:496)
	at org.testng.Assert.assertEquals(Assert.java:125)
	at org.testng.Assert.assertEquals(Assert.java:178)
	at learn.java.com.automation.Data.Login(Data.java:44)
	at sun.reflect.NativeMethodAccessorImpl.invoke0(Native Method)
	at sun.reflect.NativeMethodAccessorImpl.invoke(Unknown Source)
	at sun.reflect.DelegatingMethodAccessorImpl.invoke(Unknown Source)
	at java.lang.reflect.Method.invoke(Unknown Source)
	at org.testng.internal.MethodInvocationHelper.invokeMethod(MethodInvocationHelper.java:85)
	at org.testng.internal.Invoker.invokeMethod(Invoker.java:639)
	at org.testng.internal.Invoker.invokeTestMethod(Invoker.java:816)
	at org.testng.internal.Invoker.invokeTestMethods(Invoker.java:1124)
	at org.testng.internal.TestMethodWorker.invokeTestMethods(TestMethodWorker.java:125)
	at org.testng.internal.TestMethodWorker.run(TestMethodWorker.java:108)
	at org.testng.TestRunner.privateRun(TestRunner.java:774)
	at org.testng.TestRunner.run(TestRunner.java:624)
	at org.testng.SuiteRunner.runTest(SuiteRunner.java:359)
	at org.testng.SuiteRunner.runSequentially(SuiteRunner.java:354)
	at org.testng.SuiteRunner.privateRun(SuiteRunner.java:312)
	at org.testng.SuiteRunner.run(SuiteRunner.java:261)
	at org.testng.SuiteRunnerWorker.runSuite(SuiteRunnerWorker.java:52)
	at org.testng.SuiteRunnerWorker.run(SuiteRunnerWorker.java:86)
	at org.testng.TestNG.runSuitesSequentially(TestNG.java:1215)
	at org.testng.TestNG.runSuitesLocally(TestNG.java:1140)
	at org.testng.TestNG.run(TestNG.java:1048)
	at org.testng.remote.AbstractRemoteTestNG.run(AbstractRemoteTestNG.java:114)
	at org.testng.remote.RemoteTestNG.initAndRun(RemoteTestNG.java:251)
	at org.testng.remote.RemoteTestNG.main(RemoteTestNG.java:77)
]]>
    </failure>
  </testcase> <!-- Login -->
</testsuite> <!-- learn.java.com.automation.Data -->
